[2024-08-28T15:56:51.655+0000] {local_task_job_runner.py:123} INFO - ::group::Pre task execution logs
[2024-08-28T15:56:51.664+0000] {taskinstance.py:2603} INFO - Dependencies all met for dep_context=non-requeueable deps ti=<TaskInstance: kubernetes_pod_operator_test.start_task manual__2024-08-28T15:51:48.833513+00:00 [queued]>
[2024-08-28T15:56:51.668+0000] {taskinstance.py:2603} INFO - Dependencies all met for dep_context=requeueable deps ti=<TaskInstance: kubernetes_pod_operator_test.start_task manual__2024-08-28T15:51:48.833513+00:00 [queued]>
[2024-08-28T15:56:51.668+0000] {taskinstance.py:2856} INFO - Starting attempt 2 of 2
[2024-08-28T15:56:51.677+0000] {taskinstance.py:2879} INFO - Executing <Task(KubernetesPodOperator): start_task> on 2024-08-28 15:51:48.833513+00:00
[2024-08-28T15:56:51.681+0000] {warnings.py:112} WARNING - /home/***/.local/lib/python3.12/site-packages/***/task/task_runner/standard_task_runner.py:70: DeprecationWarning: This process (pid=792) is multi-threaded, use of fork() may lead to deadlocks in the child.
  pid = os.fork()

[2024-08-28T15:56:51.682+0000] {standard_task_runner.py:72} INFO - Started process 794 to run task
[2024-08-28T15:56:51.683+0000] {standard_task_runner.py:104} INFO - Running: ['***', 'tasks', 'run', 'kubernetes_pod_operator_test', 'start_task', 'manual__2024-08-28T15:51:48.833513+00:00', '--job-id', '18', '--raw', '--subdir', 'DAGS_FOLDER/kubernetes_test_dap.py', '--cfg-path', '/tmp/tmpxnbmu8ex']
[2024-08-28T15:56:51.683+0000] {standard_task_runner.py:105} INFO - Job 18: Subtask start_task
[2024-08-28T15:56:51.709+0000] {task_command.py:467} INFO - Running <TaskInstance: kubernetes_pod_operator_test.start_task manual__2024-08-28T15:51:48.833513+00:00 [running]> on host 65aafae803e7
[2024-08-28T15:56:51.748+0000] {taskinstance.py:3122} INFO - Exporting env vars: AIRFLOW_CTX_DAG_OWNER='***' AIRFLOW_CTX_DAG_ID='kubernetes_pod_operator_test' AIRFLOW_CTX_TASK_ID='start_task' AIRFLOW_CTX_EXECUTION_DATE='2024-08-28T15:51:48.833513+00:00' AIRFLOW_CTX_TRY_NUMBER='2' AIRFLOW_CTX_DAG_RUN_ID='manual__2024-08-28T15:51:48.833513+00:00'
[2024-08-28T15:56:51.749+0000] {logging_mixin.py:190} INFO - Task instance is in running state
[2024-08-28T15:56:51.750+0000] {logging_mixin.py:190} INFO -  Previous state of the Task instance: queued
[2024-08-28T15:56:51.750+0000] {logging_mixin.py:190} INFO - Current task name:start_task state:running start_date:2024-08-28 15:56:51.664615+00:00
[2024-08-28T15:56:51.750+0000] {logging_mixin.py:190} INFO - Dag name:kubernetes_pod_operator_test and current dag run status:running
[2024-08-28T15:56:51.751+0000] {taskinstance.py:731} INFO - ::endgroup::
[2024-08-28T15:56:51.755+0000] {pod.py:1132} INFO - Building pod ***-test-pod-4tvdq0c4 with labels: {'dag_id': 'kubernetes_pod_operator_test', 'task_id': 'start_task', 'run_id': 'manual__2024-08-28T155148.8335130000-276af6e40', 'kubernetes_pod_operator': 'True', 'try_number': '2'}
[2024-08-28T15:56:51.761+0000] {base.py:84} INFO - Retrieving connection 'kubernetes_default'
[2024-08-28T15:56:51.762+0000] {taskinstance.py:3301} ERROR - Task failed with exception
Traceback (most recent call last):
  File "/home/airflow/.local/lib/python3.12/site-packages/airflow/models/taskinstance.py", line 767, in _execute_task
    result = _execute_callable(context=context, **execute_callable_kwargs)
             ^^^^^^^^^^^^^^^^^^^^^^^^^^^^^^^^^^^^^^^^^^^^^^^^^^^^^^^^^^^^^
  File "/home/airflow/.local/lib/python3.12/site-packages/airflow/models/taskinstance.py", line 733, in _execute_callable
    return ExecutionCallableRunner(
           ^^^^^^^^^^^^^^^^^^^^^^^^
  File "/home/airflow/.local/lib/python3.12/site-packages/airflow/utils/operator_helpers.py", line 252, in run
    return self.func(*args, **kwargs)
           ^^^^^^^^^^^^^^^^^^^^^^^^^^
  File "/home/airflow/.local/lib/python3.12/site-packages/airflow/models/baseoperator.py", line 406, in wrapper
    return func(self, *args, **kwargs)
           ^^^^^^^^^^^^^^^^^^^^^^^^^^^
  File "/home/airflow/.local/lib/python3.12/site-packages/airflow/providers/cncf/kubernetes/operators/pod.py", line 592, in execute
    return self.execute_sync(context)
           ^^^^^^^^^^^^^^^^^^^^^^^^^^
  File "/home/airflow/.local/lib/python3.12/site-packages/airflow/providers/cncf/kubernetes/operators/pod.py", line 600, in execute_sync
    self.pod_request_obj = self.build_pod_request_obj(context)
                           ^^^^^^^^^^^^^^^^^^^^^^^^^^^^^^^^^^^
  File "/home/airflow/.local/lib/python3.12/site-packages/airflow/providers/cncf/kubernetes/operators/pod.py", line 1141, in build_pod_request_obj
    "airflow_kpo_in_cluster": str(self.hook.is_in_cluster),
                                  ^^^^^^^^^^^^^^^^^^^^^^^
  File "/home/airflow/.local/lib/python3.12/site-packages/airflow/providers/cncf/kubernetes/hooks/kubernetes.py", line 283, in is_in_cluster
    self.api_client  # so we can determine if we are in_cluster or not
    ^^^^^^^^^^^^^^^
  File "/usr/local/lib/python3.12/functools.py", line 993, in __get__
    val = self.func(instance)
          ^^^^^^^^^^^^^^^^^^^
  File "/home/airflow/.local/lib/python3.12/site-packages/airflow/providers/cncf/kubernetes/hooks/kubernetes.py", line 291, in api_client
    return self.get_conn()
           ^^^^^^^^^^^^^^^
  File "/home/airflow/.local/lib/python3.12/site-packages/airflow/providers/cncf/kubernetes/hooks/kubernetes.py", line 239, in get_conn
    config.load_kube_config(
  File "/home/airflow/.local/lib/python3.12/site-packages/kubernetes/config/kube_config.py", line 819, in load_kube_config
    loader = _get_kube_config_loader(
             ^^^^^^^^^^^^^^^^^^^^^^^^
  File "/home/airflow/.local/lib/python3.12/site-packages/kubernetes/config/kube_config.py", line 776, in _get_kube_config_loader
    raise ConfigException(
kubernetes.config.config_exception.ConfigException: Invalid kube-config file. No configuration found.
[2024-08-28T15:56:51.767+0000] {logging_mixin.py:190} INFO - Task instance in failure state
[2024-08-28T15:56:51.768+0000] {logging_mixin.py:190} INFO - Task start:2024-08-28 15:56:51.664615+00:00 end:2024-08-28 15:56:51.767587+00:00 duration:0.102972
[2024-08-28T15:56:51.768+0000] {logging_mixin.py:190} INFO - Task:<Task(KubernetesPodOperator): start_task> dag:<DAG: kubernetes_pod_operator_test> dagrun:<DagRun kubernetes_pod_operator_test @ 2024-08-28 15:51:48.833513+00:00: manual__2024-08-28T15:51:48.833513+00:00, state:running, queued_at: 2024-08-28 15:51:48.840802+00:00. externally triggered: True>
[2024-08-28T15:56:51.768+0000] {logging_mixin.py:190} INFO - Failure caused by Invalid kube-config file. No configuration found.
[2024-08-28T15:56:51.768+0000] {taskinstance.py:1225} INFO - Marking task as FAILED. dag_id=kubernetes_pod_operator_test, task_id=start_task, run_id=manual__2024-08-28T15:51:48.833513+00:00, execution_date=20240828T155148, start_date=20240828T155651, end_date=20240828T155651
[2024-08-28T15:56:51.775+0000] {taskinstance.py:340} INFO - ::group::Post task execution logs
[2024-08-28T15:56:51.776+0000] {standard_task_runner.py:124} ERROR - Failed to execute job 18 for task start_task (Invalid kube-config file. No configuration found.; 794)
Traceback (most recent call last):
  File "/home/airflow/.local/lib/python3.12/site-packages/airflow/task/task_runner/standard_task_runner.py", line 117, in _start_by_fork
    ret = args.func(args, dag=self.dag)
          ^^^^^^^^^^^^^^^^^^^^^^^^^^^^^
  File "/home/airflow/.local/lib/python3.12/site-packages/airflow/cli/cli_config.py", line 49, in command
    return func(*args, **kwargs)
           ^^^^^^^^^^^^^^^^^^^^^
  File "/home/airflow/.local/lib/python3.12/site-packages/airflow/utils/cli.py", line 115, in wrapper
    return f(*args, **kwargs)
           ^^^^^^^^^^^^^^^^^^
  File "/home/airflow/.local/lib/python3.12/site-packages/airflow/cli/commands/task_command.py", line 483, in task_run
    task_return_code = _run_task_by_selected_method(args, _dag, ti)
                       ^^^^^^^^^^^^^^^^^^^^^^^^^^^^^^^^^^^^^^^^^^^^
  File "/home/airflow/.local/lib/python3.12/site-packages/airflow/cli/commands/task_command.py", line 256, in _run_task_by_selected_method
    return _run_raw_task(args, ti)
           ^^^^^^^^^^^^^^^^^^^^^^^
  File "/home/airflow/.local/lib/python3.12/site-packages/airflow/cli/commands/task_command.py", line 341, in _run_raw_task
    return ti._run_raw_task(
           ^^^^^^^^^^^^^^^^^
  File "/home/airflow/.local/lib/python3.12/site-packages/airflow/utils/session.py", line 97, in wrapper
    return func(*args, session=session, **kwargs)
           ^^^^^^^^^^^^^^^^^^^^^^^^^^^^^^^^^^^^^^
  File "/home/airflow/.local/lib/python3.12/site-packages/airflow/models/taskinstance.py", line 2995, in _run_raw_task
    return _run_raw_task(
           ^^^^^^^^^^^^^^
  File "/home/airflow/.local/lib/python3.12/site-packages/airflow/models/taskinstance.py", line 273, in _run_raw_task
    TaskInstance._execute_task_with_callbacks(
  File "/home/airflow/.local/lib/python3.12/site-packages/airflow/models/taskinstance.py", line 3149, in _execute_task_with_callbacks
    result = self._execute_task(context, task_orig)
             ^^^^^^^^^^^^^^^^^^^^^^^^^^^^^^^^^^^^^^
  File "/home/airflow/.local/lib/python3.12/site-packages/airflow/models/taskinstance.py", line 3173, in _execute_task
    return _execute_task(self, context, task_orig)
           ^^^^^^^^^^^^^^^^^^^^^^^^^^^^^^^^^^^^^^^
  File "/home/airflow/.local/lib/python3.12/site-packages/airflow/models/taskinstance.py", line 767, in _execute_task
    result = _execute_callable(context=context, **execute_callable_kwargs)
             ^^^^^^^^^^^^^^^^^^^^^^^^^^^^^^^^^^^^^^^^^^^^^^^^^^^^^^^^^^^^^
  File "/home/airflow/.local/lib/python3.12/site-packages/airflow/models/taskinstance.py", line 733, in _execute_callable
    return ExecutionCallableRunner(
           ^^^^^^^^^^^^^^^^^^^^^^^^
  File "/home/airflow/.local/lib/python3.12/site-packages/airflow/utils/operator_helpers.py", line 252, in run
    return self.func(*args, **kwargs)
           ^^^^^^^^^^^^^^^^^^^^^^^^^^
  File "/home/airflow/.local/lib/python3.12/site-packages/airflow/models/baseoperator.py", line 406, in wrapper
    return func(self, *args, **kwargs)
           ^^^^^^^^^^^^^^^^^^^^^^^^^^^
  File "/home/airflow/.local/lib/python3.12/site-packages/airflow/providers/cncf/kubernetes/operators/pod.py", line 592, in execute
    return self.execute_sync(context)
           ^^^^^^^^^^^^^^^^^^^^^^^^^^
  File "/home/airflow/.local/lib/python3.12/site-packages/airflow/providers/cncf/kubernetes/operators/pod.py", line 600, in execute_sync
    self.pod_request_obj = self.build_pod_request_obj(context)
                           ^^^^^^^^^^^^^^^^^^^^^^^^^^^^^^^^^^^
  File "/home/airflow/.local/lib/python3.12/site-packages/airflow/providers/cncf/kubernetes/operators/pod.py", line 1141, in build_pod_request_obj
    "airflow_kpo_in_cluster": str(self.hook.is_in_cluster),
                                  ^^^^^^^^^^^^^^^^^^^^^^^
  File "/home/airflow/.local/lib/python3.12/site-packages/airflow/providers/cncf/kubernetes/hooks/kubernetes.py", line 283, in is_in_cluster
    self.api_client  # so we can determine if we are in_cluster or not
    ^^^^^^^^^^^^^^^
  File "/usr/local/lib/python3.12/functools.py", line 993, in __get__
    val = self.func(instance)
          ^^^^^^^^^^^^^^^^^^^
  File "/home/airflow/.local/lib/python3.12/site-packages/airflow/providers/cncf/kubernetes/hooks/kubernetes.py", line 291, in api_client
    return self.get_conn()
           ^^^^^^^^^^^^^^^
  File "/home/airflow/.local/lib/python3.12/site-packages/airflow/providers/cncf/kubernetes/hooks/kubernetes.py", line 239, in get_conn
    config.load_kube_config(
  File "/home/airflow/.local/lib/python3.12/site-packages/kubernetes/config/kube_config.py", line 819, in load_kube_config
    loader = _get_kube_config_loader(
             ^^^^^^^^^^^^^^^^^^^^^^^^
  File "/home/airflow/.local/lib/python3.12/site-packages/kubernetes/config/kube_config.py", line 776, in _get_kube_config_loader
    raise ConfigException(
kubernetes.config.config_exception.ConfigException: Invalid kube-config file. No configuration found.
[2024-08-28T15:56:51.816+0000] {local_task_job_runner.py:261} INFO - Task exited with return code 1
[2024-08-28T15:56:51.826+0000] {taskinstance.py:3891} INFO - 0 downstream tasks scheduled from follow-on schedule check
[2024-08-28T15:56:51.827+0000] {local_task_job_runner.py:240} INFO - ::endgroup::
